2021-11-26 19:58:05,673 INFO    MainThread:4816 [wandb_setup.py:_flush():71] setting env: {'api_key': '0f579240b99e6ed291924359c5de323258326760'}
2021-11-26 19:58:05,673 INFO    MainThread:4816 [wandb_setup.py:_flush():71] setting login settings: {}
2021-11-26 19:58:05,673 INFO    MainThread:4816 [wandb_init.py:_log_setup():357] Logging user logs to c:\Users\ADMIN\Desktop\Rahav\IIMB\Term5\MLOps\project\MLOps_project\notebooks\wandb\run-20211126_195805-1uaky2d7\logs\debug.log
2021-11-26 19:58:05,673 INFO    MainThread:4816 [wandb_init.py:_log_setup():358] Logging internal logs to c:\Users\ADMIN\Desktop\Rahav\IIMB\Term5\MLOps\project\MLOps_project\notebooks\wandb\run-20211126_195805-1uaky2d7\logs\debug-internal.log
2021-11-26 19:58:05,673 INFO    MainThread:4816 [wandb_init.py:init():390] calling init triggers
2021-11-26 19:58:05,690 INFO    MainThread:4816 [wandb_init.py:init():395] wandb.init called with sweep_config: {}
config: {}
2021-11-26 19:58:05,690 INFO    MainThread:4816 [wandb_init.py:init():410] re-initializing run, found existing run on stack: dbc0o6zs
2021-11-26 19:58:05,690 INFO    MainThread:4816 [wandb_run.py:finish():1347] finishing run rahav-manoharan/demo/dbc0o6zs
2021-11-26 19:58:05,873 INFO    MainThread:4816 [jupyter.py:save_history():429] not saving jupyter history
2021-11-26 19:58:05,873 INFO    MainThread:4816 [jupyter.py:save_ipynb():374] not saving jupyter notebook
2021-11-26 19:58:05,873 INFO    MainThread:4816 [wandb_init.py:_jupyter_teardown():289] cleaning up jupyter logic
2021-11-26 19:58:05,873 INFO    MainThread:4816 [wandb_run.py:_atexit_cleanup():1663] got exitcode: 0
2021-11-26 19:58:05,873 INFO    MainThread:4816 [wandb_run.py:_restore():1635] restore
2021-11-26 19:58:06,338 INFO    MainThread:4816 [wandb_run.py:_wait_for_finish():1793] got exit ret: file_counts {
  wandb_count: 1
}
pusher_stats {
  uploaded_bytes: 1187
  total_bytes: 1187
}

2021-11-26 19:58:06,819 INFO    MainThread:4816 [wandb_run.py:_wait_for_finish():1793] got exit ret: file_counts {
  wandb_count: 1
}
pusher_stats {
  uploaded_bytes: 1187
  total_bytes: 1187
}

2021-11-26 19:58:07,419 INFO    MainThread:4816 [wandb_run.py:_wait_for_finish():1793] got exit ret: file_counts {
  wandb_count: 3
}
pusher_stats {
  uploaded_bytes: 1187
  total_bytes: 4652
}

2021-11-26 19:58:07,528 INFO    MainThread:4816 [wandb_run.py:_wait_for_finish():1793] got exit ret: file_counts {
  wandb_count: 4
}
pusher_stats {
  uploaded_bytes: 1187
  total_bytes: 4678
}

2021-11-26 19:58:07,639 INFO    MainThread:4816 [wandb_run.py:_wait_for_finish():1793] got exit ret: file_counts {
  wandb_count: 4
}
pusher_stats {
  uploaded_bytes: 1187
  total_bytes: 4678
}

2021-11-26 19:58:07,752 INFO    MainThread:4816 [wandb_run.py:_wait_for_finish():1793] got exit ret: file_counts {
  wandb_count: 4
}
pusher_stats {
  uploaded_bytes: 1187
  total_bytes: 4678
}

2021-11-26 19:58:07,852 INFO    MainThread:4816 [wandb_run.py:_wait_for_finish():1793] got exit ret: file_counts {
  wandb_count: 4
}
pusher_stats {
  uploaded_bytes: 1187
  total_bytes: 4678
}

2021-11-26 19:58:07,961 INFO    MainThread:4816 [wandb_run.py:_wait_for_finish():1793] got exit ret: file_counts {
  wandb_count: 4
}
pusher_stats {
  uploaded_bytes: 4678
  total_bytes: 4678
}

2021-11-26 19:58:08,070 INFO    MainThread:4816 [wandb_run.py:_wait_for_finish():1793] got exit ret: file_counts {
  wandb_count: 4
}
pusher_stats {
  uploaded_bytes: 4678
  total_bytes: 4678
}

2021-11-26 19:58:08,186 INFO    MainThread:4816 [wandb_run.py:_wait_for_finish():1793] got exit ret: file_counts {
  wandb_count: 4
}
pusher_stats {
  uploaded_bytes: 4678
  total_bytes: 4678
}

2021-11-26 19:58:08,303 INFO    MainThread:4816 [wandb_run.py:_wait_for_finish():1793] got exit ret: file_counts {
  wandb_count: 4
}
pusher_stats {
  uploaded_bytes: 4678
  total_bytes: 4678
}

2021-11-26 19:58:08,411 INFO    MainThread:4816 [wandb_run.py:_wait_for_finish():1793] got exit ret: file_counts {
  wandb_count: 4
}
pusher_stats {
  uploaded_bytes: 4678
  total_bytes: 4678
}

2021-11-26 19:58:08,519 INFO    MainThread:4816 [wandb_run.py:_wait_for_finish():1793] got exit ret: file_counts {
  wandb_count: 4
}
pusher_stats {
  uploaded_bytes: 4678
  total_bytes: 4678
}

2021-11-26 19:58:08,636 INFO    MainThread:4816 [wandb_run.py:_wait_for_finish():1793] got exit ret: file_counts {
  wandb_count: 4
}
pusher_stats {
  uploaded_bytes: 4678
  total_bytes: 4678
}

2021-11-26 19:58:08,977 INFO    MainThread:4816 [wandb_run.py:_wait_for_finish():1793] got exit ret: file_counts {
  wandb_count: 4
}
pusher_stats {
  uploaded_bytes: 4678
  total_bytes: 4678
}

2021-11-26 19:58:09,727 INFO    MainThread:4816 [wandb_run.py:_wait_for_finish():1793] got exit ret: done: true
exit_result {
}
file_counts {
  wandb_count: 4
}
pusher_stats {
  uploaded_bytes: 4678
  total_bytes: 4678
}
local_info {
}

2021-11-26 19:58:10,845 INFO    MainThread:4816 [wandb_run.py:_append_files():2061] logging synced files
2021-11-26 19:58:10,853 INFO    MainThread:4816 [wandb_init.py:init():435] starting backend
2021-11-26 19:58:10,853 INFO    MainThread:4816 [backend.py:_multiprocessing_setup():94] multiprocessing start_methods=spawn, using: spawn
2021-11-26 19:58:10,861 INFO    MainThread:4816 [backend.py:ensure_launched():198] starting backend process...
2021-11-26 19:58:10,949 INFO    MainThread:4816 [backend.py:ensure_launched():203] started backend process with pid: 18992
2021-11-26 19:58:10,957 INFO    MainThread:4816 [wandb_init.py:init():444] backend started and connected
2021-11-26 19:58:10,973 INFO    MainThread:4816 [wandb_run.py:_label_probe_notebook():866] probe notebook
2021-11-26 19:58:10,973 INFO    MainThread:4816 [wandb_run.py:_label_probe_notebook():876] Unable to probe notebook: 'NoneType' object has no attribute 'get'
2021-11-26 19:58:10,973 INFO    MainThread:4816 [wandb_init.py:init():503] updated telemetry
2021-11-26 19:58:11,328 INFO    MainThread:4816 [wandb_init.py:init():533] communicating current version
2021-11-26 19:58:12,591 INFO    MainThread:4816 [wandb_init.py:init():538] got version response upgrade_message: "wandb version 0.12.7 is available!  To upgrade, please run:\n $ pip install wandb --upgrade"

2021-11-26 19:58:12,599 INFO    MainThread:4816 [wandb_init.py:init():548] communicating run to backend with 30 second timeout
2021-11-26 19:58:12,987 INFO    MainThread:4816 [wandb_init.py:init():576] starting run threads in backend
2021-11-26 19:58:14,119 INFO    MainThread:4816 [wandb_run.py:_console_start():1693] atexit reg
2021-11-26 19:58:14,127 INFO    MainThread:4816 [wandb_run.py:_redirect():1567] redirect: SettingsConsole.WRAP
2021-11-26 19:58:14,128 INFO    MainThread:4816 [wandb_run.py:_redirect():1604] Wrapping output streams.
2021-11-26 19:58:14,128 INFO    MainThread:4816 [wandb_run.py:_redirect():1628] Redirects installed.
2021-11-26 19:58:14,128 INFO    MainThread:4816 [wandb_init.py:init():603] run started, returning control to user process
2021-11-26 20:01:07,313 INFO    MainThread:4816 [wandb_setup.py:_flush():71] setting env: {'api_key': '0f579240b99e6ed291924359c5de323258326760'}
2021-11-26 20:01:07,313 INFO    MainThread:4816 [wandb_setup.py:_flush():71] setting login settings: {}
2021-11-26 20:01:07,313 INFO    MainThread:4816 [wandb_init.py:_log_setup():357] Logging user logs to c:\Users\ADMIN\Desktop\Rahav\IIMB\Term5\MLOps\project\MLOps_project\notebooks\wandb\run-20211126_200107-3nw1xn0b\logs\debug.log
2021-11-26 20:01:07,313 INFO    MainThread:4816 [wandb_init.py:_log_setup():358] Logging internal logs to c:\Users\ADMIN\Desktop\Rahav\IIMB\Term5\MLOps\project\MLOps_project\notebooks\wandb\run-20211126_200107-3nw1xn0b\logs\debug-internal.log
2021-11-26 20:01:07,313 INFO    MainThread:4816 [wandb_init.py:_jupyter_setup():307] configuring jupyter hooks <wandb.sdk.wandb_init._WandbInit object at 0x00000286E1D6C340>
2021-11-26 20:01:07,313 INFO    MainThread:4816 [wandb_init.py:init():390] calling init triggers
2021-11-26 20:01:07,313 INFO    MainThread:4816 [wandb_init.py:init():395] wandb.init called with sweep_config: {}
config: {}
2021-11-26 20:01:07,313 INFO    MainThread:4816 [wandb_init.py:init():410] re-initializing run, found existing run on stack: 1uaky2d7
2021-11-26 20:01:07,313 INFO    MainThread:4816 [wandb_run.py:finish():1347] finishing run rahav-manoharan/demo/1uaky2d7
2021-11-26 20:01:07,313 INFO    MainThread:4816 [wandb_run.py:_atexit_cleanup():1663] got exitcode: 0
2021-11-26 20:01:07,313 INFO    MainThread:4816 [wandb_run.py:_restore():1635] restore
2021-11-26 20:01:11,291 ERROR   MainThread:4816 [wandb_run.py:_atexit_cleanup():1681] Problem finishing run
Traceback (most recent call last):
  File "C:\Users\ADMIN\.conda\envs\mlopslab\lib\site-packages\wandb\sdk\wandb_run.py", line 1671, in _atexit_cleanup
    self._on_finish()
  File "C:\Users\ADMIN\.conda\envs\mlopslab\lib\site-packages\wandb\sdk\wandb_run.py", line 1815, in _on_finish
    self.history._flush()
  File "C:\Users\ADMIN\.conda\envs\mlopslab\lib\site-packages\wandb\sdk\wandb_history.py", line 59, in _flush
    self._callback(row=self._data, step=self._step)
  File "C:\Users\ADMIN\.conda\envs\mlopslab\lib\site-packages\wandb\sdk\wandb_run.py", line 972, in _history_callback
    self._backend.interface.publish_history(
  File "C:\Users\ADMIN\.conda\envs\mlopslab\lib\site-packages\wandb\sdk\interface\interface.py", line 505, in publish_history
    item.value_json = json_dumps_safer_history(v)  # type: ignore
  File "C:\Users\ADMIN\.conda\envs\mlopslab\lib\site-packages\wandb\util.py", line 761, in json_dumps_safer_history
    return json.dumps(obj, cls=WandBHistoryJSONEncoder, **kwargs)
  File "C:\Users\ADMIN\.conda\envs\mlopslab\lib\json\__init__.py", line 234, in dumps
    return cls(
  File "C:\Users\ADMIN\.conda\envs\mlopslab\lib\json\encoder.py", line 199, in encode
    chunks = self.iterencode(o, _one_shot=True)
  File "C:\Users\ADMIN\.conda\envs\mlopslab\lib\json\encoder.py", line 257, in iterencode
    return _iterencode(o, 0)
  File "C:\Users\ADMIN\.conda\envs\mlopslab\lib\site-packages\wandb\util.py", line 728, in default
    return json.JSONEncoder.default(self, obj)
  File "C:\Users\ADMIN\.conda\envs\mlopslab\lib\json\encoder.py", line 179, in default
    raise TypeError(f'Object of type {o.__class__.__name__} '
TypeError: Object of type Series is not JSON serializable
